Workbook

Sheet Gap Assessment
E2: Clasificación de seguridad | F2: [Insertar clasificación]
E3: Versión | F3: 1
E4: Fecha | F4: dd/mm/yy
A5: GDPR Gap Assessment | E5: Aprobado por | F5: [Nombre del encargado]
A7: Capitulo | B7: Sección | C7: Artículo | D7: Párrafo y punto | E7: Requerimiento | F7: ¿Cumple? | G7: Acción requerida para cumplir | H7: Responsable de acción
A8: CAPÍTULO I - Disposiciones generales
C9: Artículo 1 Subject-matter y objetivos | D9: Todos | E9: Ninguno - solo para información
C10: Artículo 2 Alcance material | D10: Todos | E10: ¿Se ha establecido que el RGPD se aplica a las actividades de procesamiento de datos personales que realiza la organización? | F10: Yes
C11: Artículo 3 Alcance territorial | D11: Todos | E11: ¿Se ha establecido que se aplica el RGPD, en función de los interesados cuyos datos personales procesamos? | F11: Yes
C12: Artículo 4 Definiciones | D12: Todos | E12: Ninguno - solo para información
E14: Total: | F14: =+COUNTIF(F10:F11, "Yes") -> 2
A15: CAPÍTULO II - Principios
C16: Artículo 5 - Principios referentes al tratamiento de datos personales | D16: 1a | E16: ¿Se procesan los datos personales de forma legal, justa y transparente? | F16: Yes
D17: 1b | E17: ¿Se recopilan los datos personales para fines específicos, explícitos y legítimos? | F17: Yes
D18: 1c | E18: ¿Los datos personales recopilados son adecuados, relevantes y limitados a lo necesario? | F18: Yes
D19: 1d | E19: ¿Son precisos los datos personales y, cuando es necesario, se mantienen actualizados? | F19: Yes
D20: 1e | E20: ¿Se guardan los datos personales durante más tiempo del necesario? | F20: Yes
D21: 1f | E21: ¿Se procesan los datos personales de una manera que garantice su seguridad adecuada? | F21: Yes
D22: 2 | E22: Como controlador, ¿podemos demostrar el cumplimiento de todos los principios? | F22: Yes
C23: Artículo 6 - Legalidad del procesamiento | D23: 1 | E23: ¿Se ha establecido la base legal para el procesamiento de todos los datos personales? | F23: Yes
D24: 2 | E24: Ninguno - solo para información
D25: 3 | E25: Ninguno - solo para información
D26: 4 | E26: Para procesamiento adicional, ¿se ha establecido la compatibilidad con el propósito inicial de acuerdo con los criterios requeridos? | F26: Yes
C27: Artículo 7 - Condiciones de consentimiento | D27: 1 | E27: ¿Se puede demostrar el consentimiento en todos los casos? | F27: Yes
D28: 2 | E28: ¿Todas las solicitudes de consentimiento se pueden distinguir claramente? | F28: Yes
D29: 3 | E29: ¿Hay facilidades para la retirada del consentimiento? | F29: Yes
D30: 4 | E30: ¿Se da el consentimiento de forma gratuita en todos los casos? | F30: Yes
C31: Artículo 8 - Condiciones aplicables al consentimiento de niños en relación con los servicios de la sociedad de la información | D31: Todos | E31: Para los niños, ¿se ha dado el consentimiento del titular de la responsabilidad parental en todos los casos? | F31: Yes
C32: Artículo 9 - Tratamiento de categorías especiales de datos personales | D32: Todos | E32: ¿Está claramente justificado todo el procesamiento de categorías especiales de datos personales? | F32: Yes
C33: Artículo 10 - Tratamiento de datos personales relativos a condenas penales e infracciones | D33: Todos | E33: Ninguno - solo para información
C34: Artículo 11 - Procesamiento que no requiere identificación | D34: Todos | E34: ¿Se han definido los casos de procesamiento en los que no se puede identificar al interesado? | F34: Yes
E36: Total: | F36: =+COUNTIF(F16:F34, "Yes") -> 16
A37: CAPÍTULO III - Derechos del interesado
B38: Sección 1 - Transparencia y modalidades
C39: Artículo 12 - Información, comunicación y modalidades transparentes para el ejercicio de los derechos del interesado | D39: 1 | E39: ¿Es toda la información proporcionada al interesado de una manera concisa, transparente e intelegible y de fácil acceso, utilizando un lenguaje claro y sencillo, y en los formatos requeridos? | F39: Yes
D40: 2 | E40: ¿Se facilita el ejercicio de los derechos de los interesados según sea necesario? | F40: Yes
D41: 3 | E41: ¿Se han cumplido los plazos necesarios para responder a las solicitudes de los interesados? | F41: Yes
D42: 4 | E42: ¿Se cumplen los plazos requeridos para informar al interesado cuando no se toman medidas? | F42: Yes
D43: 5 | E43: ¿Se definen criterios claros para cobrar por solicitudes manifiestamente infundadas o excesivas? | F43: Yes
D44: 6 | E44: ¿Se tienen procedimientos para confirmacion de identidad de los solicitantes? | F44: Yes
...

Sheet Resultados de cumplimiento
A3: Resultados Gap Assessment
A7: Capitulo y Sección de GDPR | B7: Número de requisitos en la sección | C7: Número de requisitos aplicables | D7: Número de requisitos aplicables cumplidos | E7: % de Cumplimiento
A8: CHAPTER I - General provisions | B8: 2 | C8: =+COUNTIF('Gap Assessment'!F9:F12,"Yes")+COUNTIF('Gap Assessment'!F9:F12,"No") -> 2 | D8: =+'Gap Assessment'!F14 -> 2 | E8: =+D8/C8 -> 1
A9: CHAPTER II - Principles | B9: 16 | C9: =+COUNTIF('Gap Assessment'!F16:F34,"Yes")+COUNTIF('Gap Assessment'!F16:F34,"No") -> 16 | D9: =+'Gap Assessment'!F36 -> 16 | E9: =+D9/C9 -> 1
A10: CHAPTER III - Section 1 - Transparency and modalities | B10: 6 | C10: =+COUNTIF('Gap Assessment'!F39:F46,"Yes")+COUNTIF('Gap Assessment'!F39:F46,"No") -> 6 | D10: =+'Gap Assessment'!F48 -> 6 | E10: =+D10/C10 -> 1
A11: CHAPTER III - Section 2 - Information and access to personal data | B11: 12 | C11: =+COUNTIF('Gap Assessment'!F50:F62,"Yes")+COUNTIF('Gap Assessment'!F50:F62,"No") -> 12 | D11: =+'Gap Assessment'!F64 -> 12 | E11: =+D11/C11 -> 1
A12: CHAPTER III - Section 3 - Rectification and erasure | B12: 10 | C12: =+COUNTIF('Gap Assessment'!F66:F77,"Yes")+COUNTIF('Gap Assessment'!F66:F77,"No") -> 10 | D12: =+'Gap Assessment'!F79 -> 9 | E12: =+D12/C12 -> 0.9
A13: CHAPTER III - Section 4 - Right to object and automated individual decision-making | B13: 9 | C13: =+COUNTIF('Gap Assessment'!F81:F90,"Yes")+COUNTIF('Gap Assessment'!F81:F90,"No") -> 9 | D13: =+'Gap Assessment'!F92 -> 9 | E13: =+D13/C13 -> 1
A14: CHAPTER III - Section 5 - Restrictions | B14: 2 | C14: =+COUNTIF('Gap Assessment'!F94:F95,"Yes")+COUNTIF('Gap Assessment'!F94:F95,"No") -> 2 | D14: =+'Gap Assessment'!F97 -> 2 | E14: =+D14/C14 -> 1
A15: CHAPTER IV - Section 1 - General obligations | B15: 24 | C15: =+COUNTIF('Gap Assessment'!F100:F131,"Yes")+COUNTIF('Gap Assessment'!F100:F131,"No") -> 24 | D15: =+'Gap Assessment'!F133 -> 24 | E15: =+D15/C15 -> 1
A16: CHAPTER IV - Section 2 - Security of personal data | B16: 13 | C16: =+COUNTIF('Gap Assessment'!F135:F147,"Yes")+COUNTIF('Gap Assessment'!F135:F147,"No") -> 13 | D16: =+'Gap Assessment'!F149 -> 12 | E16: =+D16/C16 -> 0.92307692
A17: CHAPTER IV - Section 3 - Data protection impact assessment and prior consultation | B17: 11 | C17: =+COUNTIF('Gap Assessment'!F151:F166,"Yes")+COUNTIF('Gap Assessment'!F151:F166,"No") -> 11 | D17: =+'Gap Assessment'!F168 -> 11 | E17: =+D17/C17 -> 1
A18: CHAPTER IV - Section 4 - Data protection officer | B18: 14 | C18: =+COUNTIF('Gap Assessment'!F170:F184,"Yes")+COUNTIF('Gap Assessment'!F170:F184,"No") -> 14 | D18: =+'Gap Assessment'!F186 -> 14 | E18: =+D18/C18 -> 1
A19: CHAPTER V - Transfers of personal data | B19: 9 | C19: =+COUNTIF('Gap Assessment'!F195:F220,"Yes")+COUNTIF('Gap Assessment'!F195:F220,"No") -> 9 | D19: =+'Gap Assessment'!F222 -> 9 | E19: =+D19/C19 -> 1
A20: Totales | B20: =SUM(B8:B19) -> 128 | C20: =SUM(C8:C19) -> 128 | D20: =SUM(D8:D19) -> 126 | E20: =+D20/B20 -> 0.984375

Sheet Grafico de cumplimiento

Sheet Grafico de %cumplimiento

Sheet % Radar de cumplimiento
